Workbook
Name ValidDosen: '4a'!$B$14:INDEX('4a'!$B$14:$B$1000,MAX(( '4a'!$B$14:$B$1000<>"")*(ROW('4a'!$B$14:$B$1000)-ROW('4a'!$B$14)+1)))
Name diploma: #REF!
Name diploma: #REF!
Name diploma: #REF!
Name diploma: #REF!
Name diploma: #REF!
Name diploma: #REF!
Name diploma: #REF!
Name diploma: #REF!
Name diploma: #REF!
Name diploma: #REF!
Name diploma: #REF!
Name diploma: #REF!
Name diploma: #REF!
Name diploma: #REF!
Name diploma: #REF!
Name diploma: #REF!
Name diploma: #REF!
Name diploma: #REF!
Name diploma: #REF!
Name diploma: #REF!
Name diploma: #REF!

Sheet Menu
A2: AKREDITASI PROGRAM STUDI
A3: LEMBAGA AKREDITASI MANDIRI - PROGRAM STUDI KETEKNIKAN
A5: PROGRAM AKADEMIK - VOKASI - PROGRAM PROFESI INSINYUR
C7: Perguruan Tinggi | G7: : | H7: Institut Pertanian Bogor
C9: Unit Pengelola Program Studi | G9: : | H9: Departemen Teknologi Industri Pertanian
C11: Jenis Program | G11: : | H11: Doktor
H13: Diploma Satu
H14: Diploma Dua
H15: Diploma Tiga
H16: Sarjana
H17: Sarjana Terapan
H18: Magister
H19: Magister Terapan
H20: Doktor
H21: Doktor Terapan
C23: Nama Program Studi | G23: : | H23: Teknik Industri Pertanian
H25: Unggul
H26: A
H27: Baik Sekali
H28: B
H29: Baik
H30: C
H31: Minimum
H34: Perguruan Tinggi Negeri - Satker
H35: Perguruan Tinggi Negeri - Badan Layanan Umum
H36: Perguruan Tinggi Negeri - Badan Hukum
H37: Perguruan Tinggi Swasta
C39: Alamat | G39: : | H39: Jl. Kamper Lantai 2, Gedung Fakultas Teknologi Pertanian
H41: Kampus IPB Darmaga Bogor 16002
H43: Kota/Kabupaten : | L43: Bogor | U43: Kode Pos : | W43: 16680
C45: Nomor Telepon | G45: : | H45: 62 811-1187-812
C47: E-mail | G47: : | H47: pascatip@apps.ipb.ac.id
C49: Website | G49: : | H49: http://tin.ipb.ac.id
C51: Nomor SK Pendirian PT (1) | G51: : | H51: Keputusan Menteri Perguruan Tinggi dan Ilmu Pengetahuan No. 91/1963
C53: Tanggal SK Pendirian PT | G53: : | H53: 23224
C55: Pejabat Penandatangan SK Pendirian PT | G55: : | H55: Presiden Republik Indonesia (SUKARNO)
C57: Nomor SK Pembukaan PS (2) | G57: : | H57: 584/DIKTI/Kep/1993
C59: Tanggal SK Pembukaan PS | G59: : | H59: 34244
C61: Pejabat Penandatangan SK Pembukaan PS | G61: : | H61: Rektor Institut Pertanian Bogor
C63: Tahun Pertama Kali Menerima Mahasiswa | G63: : | H63: 1993
...

Sheet Daftar Tabel
A1: DAFTAR TABEL - LAPORAN KINERJA PROGRAM STUDI - AKADEMIK VOKASI PROGRAM PROFESI INSINYUR
A3: No | B3: Nomor dan Judul Tabel | C3: Nama Sheet | E3: D1 | F3: D2 | G3: D3 | H3: S | I3: STr | J3: M | K3: MTr | L3: D | M3: DTr | N3: PSPPI | P3: Ket.
B4: Tabel Daftar Program Studi di Unit Pengelola Program Studi | C4: PS | E4: √ | F4: √ | G4: √ | H4: √ | I4: √ | J4: √ | K4: √ | L4: √ | M4: √ | P4: √ | Q4: : Diisi
B5: Tabel Disiplin Teknik Keinsinyuran yang Diselenggarakan pada Program Studi Program Profesi Insinyur | C5: PSPPI | N5: √ | Q5: : Tidak diisi
A6: 1 | B6: Tabel 1 Visi Misi Tujuan Strategi PT dan UPPS serta Visi Keilmuan Program Studi | C6: 1 | E6: √ | F6: √ | G6: √ | H6: √ | I6: √ | J6: √ | K6: √ | L6: √ | M6: √ | N6: √
A7: 2 | B7: Tabel 1 Kerjasama Tridharma Perguruan Tinggi - Pendidikan | C7: 2a1 | E7: √ | F7: √ | G7: √ | H7: √ | I7: √ | J7: √ | K7: √ | L7: √ | M7: √ | N7: √
A8: 3 | B8: Tabel 1 Kerjasama Tridharma Perguruan Tinggi - Penelitian | C8: 2a2 | E8: √ | F8: √ | G8: √ | H8: √ | I8: √ | J8: √ | K8: √ | L8: √ | M8: √ | N8: √
A9: 4 | B9: Tabel 1 Kerjasama Tridharma Perguruan Tinggi - Pengabdian kepada Masyarakat | C9: 2a3 | E9: √ | F9: √ | G9: √ | H9: √ | I9: √ | J9: √ | K9: √ | L9: √ | M9: √ | N9: √
A10: 5 | B10: Tabel 2.b) Penggunaan Dana | C10: 2b | E10: √ | F10: √ | G10: √ | H10: √ | I10: √ | J10: √ | K10: √ | L10: √ | M10: √ | N10: √
A11: 6 | B11: Tabel 3.a.1) Kurikulum dan Rencana Pembelajaran | C11: 3a1 | E11: √ | F11: √ | G11: √ | H11: √ | I11: √ | J11: √ | K11: √ | L11: √ | M11: √ | N11: √
A12: 7 | B12: Tabel 3.a.2) Mata Kuliah dan Dokumen Pembelajaran | C12: 3a2 | N12: √
A13: 8 | B13: Tabel 3.a.3) Integrasi Kegiatan Penelitian/PkM dalam Pembelajaran | C13: 3a3 | E13: √ | F13: √ | G13: √ | H13: √ | I13: √ | J13: √ | K13: √ | L13: √ | M13: √ | N13: √
A14: 9 | B14: Tabel 3.a.4) Mata Kuliah Basic Science dan Matematika dalam Proses Pembelajaran | C14: 3a4 | H14: √ | I14: √
A15: 10 | B15: Tabel 3.a.5) Capstone Design dalam Proses Pembelajaran | C15: 3a5 | H15: √ | I15: √
A16: 11 | B16: Tabel 3.b) Penelitian DTPS | C16: 3b | E16: √ | F16: √ | G16: √ | H16: √ | I16: √ | J16: √ | K16: √ | L16: √ | M16: √ | N16: √
A17: 12 | B17: Tabel 3.c) Pengabdian kepada Masyarakat DTPS | C17: 3c | E17: √ | F17: √ | G17: √ | H17: √ | I17: √ | J17: √ | K17: √ | L17: √ | M17: √ | N17: √
A18: 13 | B18: Tabel 4.a) Profil Dosen | C18: 4a | E18: √ | F18: √ | G18: √ | H18: √ | I18: √ | J18: √ | K18: √ | L18: √ | M18: √ | N18: √
A19: 14 | B19: Tabel 4.b) Data Tenaga Kependidikan Laboran / Teknisi / Administrator Sistem | C19: 4b | E19: √ | F19: √ | G19: √ | H19: √ | I19: √ | J19: √ | K19: √ | L19: √ | M19: √ | N19: √
A20: 15 | B20: Tabel 4.c) Beban Kerja (BK) Dosen Tetap Perguruan Tinggi | C20: 4c | E20: √ | F20: √ | G20: √ | H20: √ | I20: √ | J20: √ | K20: √ | L20: √ | M20: √ | N20: √
A21: 16 | B21: Tabel 4.d) Publikasi Ilmiah DTPS | C21: 4d | H21: √ | J21: √ | L21: √ | N21: √
A22: 17 | B22: Tabel 4.e) Pagelaran/Pameran/Presentasi/Publikasi Ilmiah DTPS | C22: 4e | E22: √ | F22: √ | G22: √ | I22: √ | K22: √ | M22: √ | N22: √
A23: 18 | B23: Tabel 4.f) Luaran Penelitian dan PkM oleh DTPS / DTPSPPI - HKI (Paten, Paten Sederhana) | C23: 4f-1 | E23: √ | F23: √ | G23: √ | H23: √ | I23: √ | J23: √ | K23: √ | L23: √ | M23: √ | N23: √
A24: 19 | B24: Tabel 4.f) Luaran Penelitian dan PkM oleh DTPS / DTPSPPI - HKI (Hak Cipta, Desain Produk Industri, dll.) | C24: 4f-2 | E24: √ | F24: √ | G24: √ | H24: √ | I24: √ | J24: √ | K24: √ | L24: √ | M24: √ | N24: √
A25: 20 | B25: Tabel 4.f) Luaran Penelitian dan PkM oleh DTPS / DTPSPPI - Teknologi Tepat Guna, Produk Terstandarisasi, Produk Tersertifikasi) | C25: 4f-3 | E25: √ | F25: √ | G25: √ | H25: √ | I25: √ | J25: √ | K25: √ | L25: √ | M25: √ | N25: √
A26: 21 | B26: Tabel 4.f) Luaran Penelitian dan PkM oleh DTPS / DTPSPPI - Buku ber-ISBN, Book Chapter | C26: 4f-4 | E26: √ | F26: √ | G26: √ | H26: √ | I26: √ | J26: √ | K26: √ | L26: √ | M26: √ | N26: √
A27: 22 | B27: Tabel 4.g) Produk/Jasa DTPS yang Diadopsi oleh Industri/Masyarakat | C27: 4g | E27: √ | F27: √ | G27: √ | I27: √ | K27: √ | M27: √
A28: 23 | B28: Tabel 4.h) Kinerja DTPS Dalam Mendukung Keunggulan Kompetitif | C28: 4h | H28: √ | I28: √ | J28: √ | K28: √ | L28: √ | M28: √
A29: 24 | B29: Tabel 4.i) Karya Ilmiah DTPS yang Disitasi | C29: 4i | H29: √ | I29: √ | J29: √ | K29: √ | L29: √ | M29: √
A30: 25 | B30: Tabel 4.j) Pengakuan/Rekognisi Dosen | C30: 4j | E30: √ | F30: √ | G30: √ | H30: √ | I30: √ | J30: √ | K30: √ | L30: √ | M30: √ | N30: √
A31: 26 | B31: Tabel 4.k) Pembimbing Lapangan | C31: 4k | N31: √
A32: 27 | B32: Tabel 5.a) Prasarana dan Peralatan Utama Ruang Kelas/Ruang Diskusi / Laboratorium di UPPS yang digunakan oleh PS yang Diakreditasi | C32: 5a | E32: √ | F32: √ | G32: √ | H32: √ | I32: √ | J32: √ | K32: √ | L32: √ | M32: √ | N32: √
A33: 28 | B33: Tabel 5.b) Dokumen K3L di UPPS | C33: 5b | E33: √ | F33: √ | G33: √ | H33: √ | I33: √ | J33: √ | K33: √ | L33: √ | M33: √ | N33: √
A34: 29 | B34: Tabel 5.c) Fasilitas K3L di UPPS | C34: 5c | E34: √ | F34: √ | G34: √ | H34: √ | I34: √ | J34: √ | K34: √ | L34: √ | M34: √ | N34: √
A35: 30 | B35: Tabel 6.a) Jumlah Mahasiswa (Reguler & Asing) | C35: 6a | E35: √ | F35: √ | G35: √ | H35: √ | I35: √ | J35: √ | K35: √ | L35: √ | M35: √ | N35: √
A36: 31 | B36: Tabel 6.b) IPK Lulusan | C36: 6b | E36: √ | F36: √ | G36: √ | H36: √ | I36: √ | J36: √ | K36: √ | L36: √ | M36: √ | N36: √
A37: 32 | B37: Tabel 6.c.1) Prestasi Akademik Mahasiswa | C37: 6c1 | E37: √ | F37: √ | G37: √ | H37: √ | I37: √ | J37: √ | K37: √ | L37: √ | M37: √
A38: 33 | B38: Tabel 6.c.2) Prestasi Non-akademik Mahasiswa | C38: 6c2 | E38: √ | F38: √ | G38: √ | H38: √ | I38: √
A39: 34 | B39: Tabel 6.d) Masa Studi Lulusan Program Studi | C39: 6d | E39: √ | F39: √ | G39: √ | H39: √ | I39: √ | J39: √ | K39: √ | L39: √ | M39: √ | N39: √
A40: 35 | B40: Tabel 6.e.1) Publikasi Ilmiah Mahasiswa | C40: '6e1 | H40: √ | J40: √ | L40: √
A41: 36 | B41: Tabel 6.e.2) Pagelaran/Pameran/Presentasi/Publikasi Ilmiah Mahasiswa | C41: '6e2 | I41: √ | K41: √ | M41: √
...

Sheet PS✓
A1: Tabel Daftar Program Studi di Unit Pengelola Program Studi (UPPS) | H1: <<< Daftar Tabel
B3: Status/Peringkat
B5: Terakreditasi Unggul
B6: Terakreditasi A
B7: Terakreditasi Baik Sekali
B8: Terakreditasi B
B9: Terakreditasi Baik
B10: Terakreditasi C
B11: Terakreditasi Minimum
B12: Tidak Terakreditasi
A13: Diisi oleh Program Studi Sarjana, Magister, Doktor, Diploma 1, Diploma 2, Diploma 3, Sarjana Terapan, Magister Terapan, Doktor Terapan
A14: No | B14: Jenis Program | C14: Nama Program Studi | D14: Akreditasi Program Studi | G14: Jumlah Mahasiswa saat TS
D15: Status/ Peringkat | E15: No. dan Tgl. SK | F15: Tgl. Kadaluarsa (HH/BB/TTTT)
A16: 1 | B16: 2 | C16: 3 | D16: 4 | E16: 5 | F16: 6 | G16: 7
A17: 1 | B17: Sarjana | C17: Teknik Industri Pertanian | D17: Terakreditasi Unggul | E17: 290/SK/BAN-PT/Akred-Itnl/S/VI/2023; 13 Juni 2023 | F17: 46843 | G17: 491
A18: 2 | B18: Magister | C18: Teknik Industri Pertanian | D18: Terakreditasi Unggul | E18: 0395/SK/LAM Teknik/AM/VIII/2025 | F18: 47715 | G18: 55
A19: 3 | B19: Doktor | C19: Teknik Industri Pertanian | D19: Terakreditasi Unggul | E19: 379/SK/BAN-PT/Ak-PPJ/D/I/2022 | F19: 46246 | G19: 73
A20: 4 | G20: =SUM(G17:G19) -> 619

Sheet 1 ✓
A1: Tabel 1 Visi Misi Tujuan Strategi Perguruan Tinggi dan UPPS serta Visi Keilmuan Program Studi | F1: <<< Daftar Tabel
A3: Diisi oleh pengusul dari Program Studi untuk semua program
A4: No. | B4: Jenis VMTS | C4: Pernyataan | D4: No. Surat keputusan (SK) | E4: Link Dokumen
A6: 1 | B6: 2 | C6: 3 | D6: 4 | E6: 5
A7: 1 | B7: VMTS PT | E7: Keputusan Menteri Pendirian IPB (1-9-1963).pdf
A8: 2 | B8: Visi | C8: Menjadi perguruan tinggi berbasis riset dan terdepan dalam inovasi untuk kemandirian bangsa menuju techno-socio entrepreneurial university yang unggul di tingkat global pada bidang pertanian, kelautan, biosains tropika. | D8: Keputusan Menteri Perguruan Tinggi dan Ilmu Pengetahuan (PTIP) No. 91 Tahun 1963
A9: 3 | B9: Misi | C9: 1. Menyelenggarakan pendidikan tinggi dengan melakukan penguatan research base university agar menghasilkan lulusan techno-sociopreneur yang unggul, memiliki akhlak mulia yang berlandaskan iman dan takwa kepada Tuhan Yang Maha Esa, nasionalisme tinggi, kompetensi profesional, softskills millennium, jiwa kepemimpinan, berwawasan global dan menjadi trend setter inovasi dan perubahan. 2. Memelopori penelitian unggul dan terdepan dalam IPTEKS yang transformatif untuk terciptanya kualitas kehidupan berkelanjutan, serta inovasi untuk ekonomi rakyat dan industri nasional. 3. Mendalami ilmu-ilmu terkini di bidang pertanian, kelautan dan biosains tropika untuk menjadi penentu kecenderungan ilmu terkini di tingkat nasional dan global. 4. Meningkatkan layanan proaktif yang berkontribusi dan memecahkan persoalan masyarakat dan meningkatkan peran IPB dalam menentukan arah kebijakan nasional. 5. Memperkuat sistem manajemen PT yang mampu menjadi pedoman pengembangan sistem manajemen modern pendidikan tinggi di era 4.0.
A10: 4 | B10: Tujuan | C10: 1. Menghasilkan lulusan techno-sociopreneur unggul yg memiliki akhlak mulia berlandaskan iman dan takwa kepada Tuhan Yang Maha Esa, nasionalisme tinggi, kompetensi profesional, softskills milenium, jiwa kepemimpinan, berwawasan global dan menjadi trend setter inovasi dan perubahan. 2. Menghasilkan ilmu pengetahuan, teknologi, dan seni yang transformatif untuk terciptanya kualitas kehidupan berkelanjutan, serta inovasi konkrit untuk ekonomi rakyat dan industri nasional. 3. Menjadikan IPB sebagai penentu kecenderungan ilmu-ilmu terkini di bidang pertanian, kelautan dan biosains tropika di tingkat nasional dan global. 4. Menjadikan IPB sebagai perguruan tinggi proaktif memecahkan persoalan masyarakat dan penentu arah kebijakan nasional. 5. Menjadikan IPB sebagai pelopor pengembangan sistem manajemen modern pendidikan tinggi.
A11: 5 | B11: Strategi | C11: Berdasarkan dokumen rencana strategis IPB 2024-2028, sasaran strategis IPB adalah: 1. IPB sebagai pencetak future fit-in graduates/learners, yaitu techno-sociopreneur unggul yang memiliki akhlah mulia, pola pikir tumbuh, nasionalisme tinggi, skillset masa depan dengan agilitas pola pikir, profesional, berwawasan global, komitmen keberlanjutan, serta mampu menjadi pemimpin perubahan 2. IPB sebagai penggerak riset & inovasi unggul yang berdampak pada kualitas keidupan berkelanjutan 3. IPB sebagai penentu visi keilmuan (science vision) di bidang pertanian, kelautan, dan biosain tropika di tingkat nasional dan global 4. IPB sebagai perguruan tinggi yang selalu proaktif membangun resiliensi msyarakat dna penentu arah kebijakan 5. IPB sebagai pelopor sistem manajemen pendidikan tinggi yang resilien dan transformatif
A12: 6 | B12: VMTS UPPS | D12: 001/K13/PP/2005 | E12: 001-K13-PP-2005 Penataan Departemen di Lingkungan IPB Mandat Departemen.pdf
A13: 7 | B13: Visi | C13: Menjadi program studi yang unggul dan bertaraf internasional dalam menghasilkan sumber daya manusia yang berkualitas dalam bidang teknologi dan manajemen agroindustri.
A14: 8 | B14: Misi | C14: Menyelenggarakan pendidikan, penelitian dan pengabdian kepada masyarakat dalam bidang agroindustri dengan fokus pada: 1. Perbaikan berkelanjutan terhadap kualitas pendidikan yang mencakup aspek SDM, sarana dan prasarana, kurikulum (proses pembelajaran dan penilaiannya), dan pengelolaan serta pelayanan dalam menghasilkan lulusan yang berkualitas, 2. Peningkatan kualitas penelitian dan penguatan keterkaitannya dengan kebutuhan stakeholder serta berkontribusi terhadap pengembangan IPTEK melalui kerjasama nasional / internasional, dan 3. Intensifikasi dan ekstensifikasi kegiatan transfer teknologi kepada masyarakat untuk meningkatkan kesejahteraannya.
A15: 9 | B15: Tujuan | C15: 1. Menghasilkan lulusan yang : i) Mampu berkarir di bidang agroindustri dengan melibatkan pekerjaan perencanaan, perancangan, implementasi, pengendalian dan pengembangan sistem agroindustri berkesinambungan, mencakup aspek manajerial, teknologi proses dan lingkungan; ii) Mampu mengembangkan pengetahuan dan kemampuan diri melalui studi ke jenjang yang lebih tinggi sesuai dengan kebutuhan pengembangan agroindustri; iii) Mampu berkarir di bidang pekerjaan yang terkait dengan teknologi industri baik sebagai profesional atau berkarya sebagai technopreneur untuk mencapai kesejahteraan bagi dirinya maupun bagi masyarakat dan kemajuan bangsa. 2. Menghasilkan produk penelitian dan pengembangan yang berkontribusi dalam pembangunan agroindustri dan IPTEK, dan 3. Mendiseminasikan dan mempromosikan penerapan produk penelitian dan temuan inovatif dalam aspek teknologi proses dan teknik agroindustri yang berwawasan lingkungan kepada pihak pemangku kepentingan (stakeholders).
A16: 10 | B16: Strategi | C16: 1. Strategi dalam bidang pendidikan, yaitu: 1) Pengembangan kurikulum yang relevan dan berkualitas sesuai dengan kebutuhan dunia kerja, perkembangan ilmu pengetahuan, dan industri agar lulusan memiliki kompetensi yang dibutuhkan masyarakat; 2) Penerapan metode pembelajaran efektif dan inovatif, termasuk pemanfaatan teknologi digital dan sistem informasi akademik (SIMAK) untuk mendukung proses belajar mengajar yang adaptif dan efisien; 3) Monitoring dan evaluasi berkala terhadap proses pendidikan untuk memastikan mutu dan pencapaian tujuan pembelajaran; 4) Pengembangan kompetensi dosen melalui pelatihan, penelitian, dan pengembangan diri agar mampu memberikan pengajaran yang bermutu dan sesuai standar akademik; 5) Penguatan soft skills dan karakter mahasiswa melalui kegiatan ekstrakurikuler dan pembinaan agar lulusan siap bersaing dan berkontribusi di masyarakat. 2. Strategi dalam bidang penelitian adalah: 1) Mendorong budaya penelitian aktif di kalangan dosen dan mahasiswa dengan menyediakan fasilitas yang memadai; 2) Fokus pada penelitian yang relevan dan aplikatif untuk menjawab permasalahan nyata dan berkontribusi pada pengembangan ilmu pengetahuan, teknologi, dan seni; 3) Publikasi hasil penelitian secara berkala di jurnal ilmiah nasional dan internasional untuk menyebarluaskan ilmu dan meningkatkan reputasi akademik; 4) Pengembangan kerjasama penelitian dengan institusi lain, baik nasional maupun internasional, untuk memperluas jaringan dan sumber daya penelitian; 5. Evaluasi dan monitoring kinerja penelitian sebagai bagian dari sistem penjaminan mutu tridharma perguruan tinggi. 3. Strategi dalam bidang pengabdian kepada masyarakat adalah: 1) Pelaksanaan program pengabdian yang sesuai dengan kebutuhan dan potensi lokal masyarakat, sehingga memberikan kontribusi positif dan nyata; 2) Mengaktifkan partisipasi dosen dan mahasiswa dalam kegiatan pengabdian masyarakat sebagai wujud integrasi ilmu pengetahuan dengan kebutuhan Masyarakat; 3) Evaluasi dan pelaporan hasil pengabdian untuk memastikan kebermanfaatan dan keberlanjutan program; 4) Pengembangan kemitraan dengan berbagai pihak seperti pemerintah, industri, dan komunitas lokal untuk memperkuat dampak pengabdian masyarakat.
A17: 11 | B17: Visi Keilmuan PS | D17: 379/SK/BAN-PT/Ak-PPj/D/J/2022 031/K13/PP/2002 | E17: Ijin Pendirian Prodi S3 TIP-2002.pdf
A18: 12 | B18: Visi | C18: Menjadi program studi doctor unggulan yang menghasilkan lulusan berkompetensi tinggi dalam Teknik industry pertanian, mampu menghadapi tantangan global melalui inovasi, keberlanjutan, dan teknologi mutakhir untuk decade mendatang.
A19: 13
A20: 14
A21: 15
A22: 16
A23: 17
A24: 18
A25: 19
A26: 20
A27: 21
A28: 22
A29: 23
A30: 24
... A106: 100

Sheet 2a1
A1: Tabel 2 Kerjasama Tridharma Perguruan Tinggi | F1: sudah ada bukti | M1: <<< Daftar Tabel
A2: Tabel 2 Bagian-1 Kerjasama Pendidikan
A3: Diisi oleh pengusul dari Program Studi untuk semua program
G4: Validitas Kerjasama | L4: Surat Penugasan
G5: TS-3 | H5: =IF(ISBLANK(Menu!S73),"",DATE(YEAR(Menu!S73)-4,MONTH(Menu!S73),DAY(Menu!S73))) | L5: Surat Perjanjian Kerjasama (SPK)
B6: Check | L6: Bukti-bukti Pelaksanaan (Laporan, Hasil Kerjasama, Luaran Kerjasama)
L7: Bukti lain yang relevan
B8: V
A10: No. | B10: Lembaga Mitra | C10: Tingkat | F10: Judul Kegiatan Kerjasama | G10: Manfaat bagi PS yang Diakreditasi | H10: Tanggal Awal Kerjasama (HH/BB/TTTT) | I10: Tanggal Akhir Kerjasama (HH/BB/TTTT) | J10: Durasi (dalam tahun) | K10: Status Kerjasama | L10: Bukti Kerjasama
C11: Interna-sional | D11: Nasional | E11: Lokal/Wilayah
A12: 1 | B12: 2 | C12: 3 | D12: 4 | E12: 5 | F12: 6 | G12: 7 | H12: 8 | I12: 9 | J12: 10 | K12: 11 | L12: 12
A13: 1 | B13: Wocare Center | D13: V | F13: Kerjasama Pendidikan dan Penelitian Tugas Akhir Produta dan Proyek Investigasi | G13: Peningkatan Kualitas Pendidikan, Transfer Pengetahuan, Penelitian | H13: 45139 | I13: 45534 | J13: 1 | K13: =IF(OR(ISBLANK(H13),ISBLANK(I13),ISBLANK(H5)),"",IF(OR(AND(H13>H5,H13<Menu!S73),AND(I13>H5,I13<Menu!S73),AND(H13<H5,I13>Menu!S73)),"Valid","Tidak Valid")) -> Valid | L13: Bukti-bukti Pelaksanaan (Laporan, Hasil Kerjasama, Luaran Kerjasama) | P13: Info:
A14: 2 | B14: PT. Toyota Motor Manufacturing Indonesia | D14: V | F14: Kerjasama Pendidikan dan Penelitian Tugas Akhir Produta | G14: Peningkatan Kualitas Pendidikan, Transfer Pengetahuan, Penelitian | H14: 45323 | I14: 45534 | J14: 0 | K14: =IF(OR(ISBLANK(H14),ISBLANK(I14),ISBLANK(H5)),"",IF(OR(AND(H14>H5,H14<Menu!S73),AND(I14>H5,I14<Menu!S73),AND(H14<H5,I14>Menu!S73)),"Valid","Tidak Valid")) -> Valid | L14: Bukti-bukti Pelaksanaan (Laporan, Hasil Kerjasama, Luaran Kerjasama) | P14: Jumlah Kerjasama Pendidikan | S14: =SUM(S17,S20,S23) -> 93
A15: 3 | B15: PT. Berkasih Sinar Utami | D15: V | F15: Kerjasama Pendidikan dan Penelitian Tugas Akhir Produta | G15: Peningkatan Kualitas Pendidikan, Transfer Pengetahuan, Penelitian | H15: 45323 | I15: 45534 | J15: 0 | K15: =IF(OR(ISBLANK(H15),ISBLANK(I15),ISBLANK(H5)),"",IF(OR(AND(H15>H5,H15<Menu!S73),AND(I15>H5,I15<Menu!S73),AND(H15<H5,I15>Menu!S73)),"Valid","Tidak Valid")) -> Valid | L15: Bukti-bukti Pelaksanaan (Laporan, Hasil Kerjasama, Luaran Kerjasama) | M15: Laporan akhir sama dengan toyota
A16: 4 | B16: PT. Eteris Prima Wiyasa | D16: V | F16: Kerjasama Pendidikan dan Penelitian Tugas Akhir Produta | G16: Peningkatan Kualitas Pendidikan, Transfer Pengetahuan, Penelitian | H16: 45323 | I16: 45899 | J16: 1 | K16: =IF(OR(ISBLANK(H16),ISBLANK(I16),ISBLANK(H5)),"",IF(OR(AND(H16>H5,H16<Menu!S73),AND(I16>H5,I16<Menu!S73),AND(H16<H5,I16>Menu!S73)),"Valid","Tidak Valid")) -> Valid | L16: Bukti-bukti Pelaksanaan (Laporan, Hasil Kerjasama, Luaran Kerjasama)
A17: 5 | B17: PT. Essodev Agro Lestari | D17: V | F17: Kerjasama Pendidikan dan Penelitian Tugas Akhir Produta | G17: Peningkatan Kualitas Pendidikan, Transfer Pengetahuan, Penelitian | H17: 45323 | I17: 45534 | J17: 0 | K17: =IF(OR(ISBLANK(H17),ISBLANK(I17),ISBLANK(H5)),"",IF(OR(AND(H17>H5,H17<Menu!S73),AND(I17>H5,I17<Menu!S73),AND(H17<H5,I17>Menu!S73)),"Valid","Tidak Valid")) -> Valid | L17: Bukti-bukti Pelaksanaan (Laporan, Hasil Kerjasama, Luaran Kerjasama) | P17: Jumlah Kerjasama Tingkat Internasional | S17: =COUNTIFS(B13:B996,"<>",C13:C996,"<>",F13:F996,"<>",J13:J996,"<>",K13:K996,"Valid",L13:L996,"<>",C13:C996,"V") -> 19
A18: 6 | B18: PT. Kelola Mina Laut | D18: V | F18: Kerjasama Pendidikan dan Penelitian Tugas Akhir Produta | G18: Peningkatan Kualitas Pendidikan, Transfer Pengetahuan, Penelitian | H18: 45323 | I18: 45534 | J18: 0 | K18: =IF(OR(ISBLANK(H18),ISBLANK(I18),ISBLANK(H5)),"",IF(OR(AND(H18>H5,H18<Menu!S73),AND(I18>H5,I18<Menu!S73),AND(H18<H5,I18>Menu!S73)),"Valid","Tidak Valid")) -> Valid | L18: Bukti-bukti Pelaksanaan (Laporan, Hasil Kerjasama, Luaran Kerjasama)
A19: 7 | B19: PT. Laris Manis Utama | D19: V | F19: Kerjasama Pendidikan dan Penelitian Tugas Akhir Produta | G19: Peningkatan Kualitas Pendidikan, Transfer Pengetahuan, Penelitian | H19: 44247 | I19: 45343 | J19: 3 | K19: =IF(OR(ISBLANK(H19),ISBLANK(I19),ISBLANK(H5)),"",IF(OR(AND(H19>H5,H19<Menu!S73),AND(I19>H5,I19<Menu!S73),AND(H19<H5,I19>Menu!S73)),"Valid","Tidak Valid")) -> Valid | L19: Bukti-bukti Pelaksanaan (Laporan, Hasil Kerjasama, Luaran Kerjasama)
A20: 8 | B20: PT. Cinta Bumi Nusantara | D20: V | F20: Kerjasama Pendidikan dan Penelitian Tugas Akhir Produta | G20: Peningkatan Kualitas Pendidikan, Transfer Pengetahuan, Penelitian | H20: 45323 | I20: 45534 | J20: 0 | K20: =IF(OR(ISBLANK(H20),ISBLANK(I20),ISBLANK(H5)),"",IF(OR(AND(H20>H5,H20<Menu!S73),AND(I20>H5,I20<Menu!S73),AND(H20<H5,I20>Menu!S73)),"Valid","Tidak Valid")) -> Valid | L20: Bukti-bukti Pelaksanaan (Laporan, Hasil Kerjasama, Luaran Kerjasama) | P20: Jumlah Kerjasama Tingkat Nasional | S20: =COUNTIFS(B13:B996,"<>",D13:D996,"<>",F13:F996,"<>",J13:J996,"<>",K13:K996,"Valid",L13:L996,"<>",D13:D996,"V") -> 67
A21: 9 | B21: PT. Agro Boga Utama | D21: V | F21: Kerjasama Pendidikan dan Penelitian Tugas Akhir Produta | G21: Peningkatan Kualitas Pendidikan, Transfer Pengetahuan, Penelitian | H21: 44593 | I21: 45899 | J21: 3 | K21: =IF(OR(ISBLANK(H21),ISBLANK(I21),ISBLANK(H5)),"",IF(OR(AND(H21>H5,H21<Menu!S73),AND(I21>H5,I21<Menu!S73),AND(H21<H5,I21>Menu!S73)),"Valid","Tidak Valid")) -> Valid | L21: Bukti-bukti Pelaksanaan (Laporan, Hasil Kerjasama, Luaran Kerjasama)
A22: 10 | B22: Aquila Herb | D22: V | F22: Kerjasama Pendidikan dan Penelitian Tugas Akhir Produta | G22: Peningkatan Kualitas Pendidikan, Transfer Pengetahuan, Penelitian | H22: 45323 | I22: 45534 | J22: 0 | K22: =IF(OR(ISBLANK(H22),ISBLANK(I22),ISBLANK(H5)),"",IF(OR(AND(H22>H5,H22<Menu!S73),AND(I22>H5,I22<Menu!S73),AND(H22<H5,I22>Menu!S73)),"Valid","Tidak Valid")) -> Valid | L22: Bukti-bukti Pelaksanaan (Laporan, Hasil Kerjasama, Luaran Kerjasama)
A23: 11 | B23: PT. Tanjung Enim Utama Pulp and Papper | D23: V | F23: Kerjasama Pendidikan dan Penelitian Tugas Akhir Produta | G23: Peningkatan Kualitas Pendidikan, Transfer Pengetahuan, Penelitian | H23: 45323 | I23: 45534 | J23: 0 | K23: =IF(OR(ISBLANK(H23),ISBLANK(I23),ISBLANK(H5)),"",IF(OR(AND(H23>H5,H23<Menu!S73),AND(I23>H5,I23<Menu!S73),AND(H23<H5,I23>Menu!S73)),"Valid","Tidak Valid")) -> Valid | L23: Bukti-bukti Pelaksanaan (Laporan, Hasil Kerjasama, Luaran Kerjasama) | P23: Jumlah Kerjasama Tingkat Lokal/Wilayah | S23: =COUNTIFS(B13:B996,"<>",E13:E996,"<>",F13:F996,"<>",J13:J996,"<>",K13:K996,"Valid",L13:L996,"<>",E13:E996,"V") -> 7
A24: 12 | B24: Pengrajin Batik Lasem | D24: V | F24: Kerjasama Pendidikan dan Penelitian Tugas Akhir Produta | G24: Peningkatan Kualitas Pendidikan, Transfer Pengetahuan, Penelitian | H24: 45323 | I24: 45534 | J24: 0 | K24: =IF(OR(ISBLANK(H24),ISBLANK(I24),ISBLANK(H5)),"",IF(OR(AND(H24>H5,H24<Menu!S73),AND(I24>H5,I24<Menu!S73),AND(H24<H5,I24>Menu!S73)),"Valid","Tidak Valid")) -> Valid | L24: Bukti lain yang relevan | M24: https://drive.google.com/drive/folders/1lSq1GKFMnopKOEGem8NwI6w4vQvNWJsE
A25: 13 | B25: Pondok Sagu Metro | D25: V | F25: Kerjasama Pendidikan dan Penelitian Tugas Akhir Produta | G25: Peningkatan Kualitas Pendidikan, Transfer Pengetahuan, Penelitian | H25: 44593 | I25: 45899 | J25: 2 | K25: =IF(OR(ISBLANK(H25),ISBLANK(I25),ISBLANK(H5)),"",IF(OR(AND(H25>H5,H25<Menu!S73),AND(I25>H5,I25<Menu!S73),AND(H25<H5,I25>Menu!S73)),"Valid","Tidak Valid")) -> Valid | L25: Bukti-bukti Pelaksanaan (Laporan, Hasil Kerjasama, Luaran Kerjasama)
A26: 14 | B26: PT. Karya Baru Kita | D26: V | F26: Kerjasama Pendidikan dan Penelitian Tugas Akhir Produta | G26: Peningkatan Kualitas Pendidikan, Transfer Pengetahuan, Penelitian | H26: 45323 | I26: 45534 | J26: 0 | K26: =IF(OR(ISBLANK(H26),ISBLANK(I26),ISBLANK(H5)),"",IF(OR(AND(H26>H5,H26<Menu!S73),AND(I26>H5,I26<Menu!S73),AND(H26<H5,I26>Menu!S73)),"Valid","Tidak Valid")) -> Valid | L26: Bukti-bukti Pelaksanaan (Laporan, Hasil Kerjasama, Luaran Kerjasama)
A27: 15 | B27: PT. Unilever Indonesia, Tbk. | D27: V | F27: Kerjasama Pendidikan dan Penelitian Tugas Akhir Produta | G27: Peningkatan Kualitas Pendidikan, Transfer Pengetahuan, Penelitian | H27: 45323 | I27: 45534 | J27: 0 | K27: =IF(OR(ISBLANK(H27),ISBLANK(I27),ISBLANK(H5)),"",IF(OR(AND(H27>H5,H27<Menu!S73),AND(I27>H5,I27<Menu!S73),AND(H27<H5,I27>Menu!S73)),"Valid","Tidak Valid")) -> Valid | L27: Bukti-bukti Pelaksanaan (Laporan, Hasil Kerjasama, Luaran Kerjasama)
A28: 16 | B28: PT. Primafood Relasi Utama | D28: V | F28: Kerjasama Pendidikan dan Penelitian Tugas Akhir Produta | G28: Peningkatan Kualitas Pendidikan, Transfer Pengetahuan, Penelitian | H28: 45323 | I28: 45534 | J28: 0 | K28: =IF(OR(ISBLANK(H28),ISBLANK(I28),ISBLANK(H5)),"",IF(OR(AND(H28>H5,H28<Menu!S73),AND(I28>H5,I28<Menu!S73),AND(H28<H5,I28>Menu!S73)),"Valid","Tidak Valid")) -> Valid | L28: Bukti-bukti Pelaksanaan (Laporan, Hasil Kerjasama, Luaran Kerjasama)
A29: 17 | B29: PT. LeGGit Boga Mandiri | D29: V | F29: Kerjasama Pendidikan dan Penelitian Tugas Akhir Produta | G29: Peningkatan Kualitas Pendidikan, Transfer Pengetahuan, Penelitian | H29: 44958 | I29: 45899 | J29: 2 | K29: =IF(OR(ISBLANK(H29),ISBLANK(I29),ISBLANK(H5)),"",IF(OR(AND(H29>H5,H29<Menu!S73),AND(I29>H5,I29<Menu!S73),AND(H29<H5,I29>Menu!S73)),"Valid","Tidak Valid")) -> Valid | L29: Bukti-bukti Pelaksanaan (Laporan, Hasil Kerjasama, Luaran Kerjasama)
A30: 18 | B30: BUMD Dharma Jaya | D30: V | F30: Kerjasama Pendidikan dan Penelitian Tugas Akhir Produta | G30: Peningkatan Kualitas Pendidikan, Transfer Pengetahuan, Penelitian | H30: 44958 | I30: 45534 | J30: 0 | K30: =IF(OR(ISBLANK(H30),ISBLANK(I30),ISBLANK(H5)),"",IF(OR(AND(H30>H5,H30<Menu!S73),AND(I30>H5,I30<Menu!S73),AND(H30<H5,I30>Menu!S73)),"Valid","Tidak Valid")) -> Valid | L30: Bukti-bukti Pelaksanaan (Laporan, Hasil Kerjasama, Luaran Kerjasama)
A31: 19 | B31: PT. Alam Indonesia Raharja | D31: V | F31: Kerjasama Pendidikan dan Penelitian Tugas Akhir Produta | G31: Peningkatan Kualitas Pendidikan, Transfer Pengetahuan, Penelitian | H31: 45323 | I31: 45534 | J31: 0 | K31: =IF(OR(ISBLANK(H31),ISBLANK(I31),ISBLANK(H5)),"",IF(OR(AND(H31>H5,H31<Menu!S73),AND(I31>H5,I31<Menu!S73),AND(H31<H5,I31>Menu!S73)),"Valid","Tidak Valid")) -> Valid | L31: Bukti-bukti Pelaksanaan (Laporan, Hasil Kerjasama, Luaran Kerjasama)
A32: 20 | B32: CV. Bio Chitosan Indonesia | D32: V | F32: Kerjasama Pendidikan dan Penelitian Tugas Akhir Produta | G32: Peningkatan Kualitas Pendidikan, Transfer Pengetahuan, Penelitian | H32: 45323 | I32: 45534 | J32: 0 | K32: =IF(OR(ISBLANK(H32),ISBLANK(I32),ISBLANK(H5)),"",IF(OR(AND(H32>H5,H32<Menu!S73),AND(I32>H5,I32<Menu!S73),AND(H32<H5,I32>Menu!S73)),"Valid","Tidak Valid")) -> Valid | L32: Bukti-bukti Pelaksanaan (Laporan, Hasil Kerjasama, Luaran Kerjasama)
A33: 21 | B33: Perum BULOG | D33: V | F33: Kerjasama Pendidikan dan Penelitian Tugas Akhir Produta | G33: Peningkatan Kualitas Pendidikan, Transfer Pengetahuan, Penelitian | H33: 44593 | I33: 45899 | J33: 2 | K33: =IF(OR(ISBLANK(H33),ISBLANK(I33),ISBLANK(H5)),"",IF(OR(AND(H33>H5,H33<Menu!S73),AND(I33>H5,I33<Menu!S73),AND(H33<H5,I33>Menu!S73)),"Valid","Tidak Valid")) -> Valid | L33: Surat Perjanjian Kerjasama (SPK)
A34: 22 | B34: Koperasi Jasa Amanah Madani Halal (SIJAMAL) | F34: Kerjasama Pendidikan dan Penelitian Tugas Akhir Produta | G34: Peningkatan Kualitas Pendidikan, Transfer Pengetahuan, Penelitian | H34: 45323 | I34: 45534 | J34: 0 | K34: =IF(OR(ISBLANK(H34),ISBLANK(I34),ISBLANK(H5)),"",IF(OR(AND(H34>H5,H34<Menu!S73),AND(I34>H5,I34<Menu!S73),AND(H34<H5,I34>Menu!S73)),"Valid","Tidak Valid")) -> Valid | L34: Bukti-bukti Pelaksanaan (Laporan, Hasil Kerjasama, Luaran Kerjasama)
A35: 23 | B35: PT. Liza Herbal Internasional | D35: V | F35: Kerjasama Pendidikan dan Penelitian Tugas Akhir Produta | G35: Peningkatan Kualitas Pendidikan, Transfer Pengetahuan, Penelitian | H35: 44958 | I35: 45534 | J35: 2 | K35: =IF(OR(ISBLANK(H35),ISBLANK(I35),ISBLANK(H5)),"",IF(OR(AND(H35>H5,H35<Menu!S73),AND(I35>H5,I35<Menu!S73),AND(H35<H5,I35>Menu!S73)),"Valid","Tidak Valid")) -> Valid | L35: Bukti-bukti Pelaksanaan (Laporan, Hasil Kerjasama, Luaran Kerjasama)
A36: 24 | B36: PT. Sukaraja Pangan Utama | D36: V | F36: Kerjasama Pendidikan dan Penelitian Tugas Akhir Produta | G36: Peningkatan Kualitas Pendidikan, Transfer Pengetahuan, Penelitian | H36: 44958 | I36: 45534 | J36: 2 | K36: =IF(OR(ISBLANK(H36),ISBLANK(I36),ISBLANK(H5)),"",IF(OR(AND(H36>H5,H36<Menu!S73),AND(I36>H5,I36<Menu!S73),AND(H36<H5,I36>Menu!S73)),"Valid","Tidak Valid")) -> Valid | L36: Bukti lain yang relevan | M36: https://drive.google.com/drive/folders/1lSq1GKFMnopKOEGem8NwI6w4vQvNWJsE
A37: 25 | B37: PT. Ratu Bio Indonesia | D37: V | F37: Kerjasama Pendidikan dan Penelitian Tugas Akhir Produta dan Magang MBKM | G37: Peningkatan Kualitas Pendidikan, Transfer Pengetahuan, Penelitian | H37: 44958 | I37: 45899 | J37: 2 | K37: =IF(OR(ISBLANK(H37),ISBLANK(I37),ISBLANK(H5)),"",IF(OR(AND(H37>H5,H37<Menu!S73),AND(I37>H5,I37<Menu!S73),AND(H37<H5,I37>Menu!S73)),"Valid","Tidak Valid")) -> Valid | L37: Bukti-bukti Pelaksanaan (Laporan, Hasil Kerjasama, Luaran Kerjasama)
A38: 26 | B38: PT. Pertamina (Persero) | D38: V | F38: Kerjasama Pendidikan dan Penelitian Tugas Akhir Produta | G38: Peningkatan Kualitas Pendidikan, Transfer Pengetahuan, Penelitian | H38: 44958 | I38: 45899 | J38: 2 | K38: =IF(OR(ISBLANK(H38),ISBLANK(I38),ISBLANK(H5)),"",IF(OR(AND(H38>H5,H38<Menu!S73),AND(I38>H5,I38<Menu!S73),AND(H38<H5,I38>Menu!S73)),"Valid","Tidak Valid")) -> Valid | L38: Bukti-bukti Pelaksanaan (Laporan, Hasil Kerjasama, Luaran Kerjasama)
A39: 27 | B39: BRIX Stevia | D39: V | F39: Kerjasama Pendidikan dan Penelitian Tugas Akhir Produta | G39: Peningkatan Kualitas Pendidikan, Transfer Pengetahuan, Penelitian | H39: 44958 | I39: 45899 | J39: 2 | K39: =IF(OR(ISBLANK(H39),ISBLANK(I39),ISBLANK(H5)),"",IF(OR(AND(H39>H5,H39<Menu!S73),AND(I39>H5,I39<Menu!S73),AND(H39<H5,I39>Menu!S73)),"Valid","Tidak Valid")) -> Valid | L39: Bukti-bukti Pelaksanaan (Laporan, Hasil Kerjasama, Luaran Kerjasama)
A40: 28 | B40: Nong Lam University, Vietnam | C40: V | F40: Kerjasama Pendidikan Perkuliahan Summer Course | G40: Peningkatan Kualitas Pendidikan, Transfer Pengetahuan, Penelitian | H40: 45078 | I40: 45657 | J40: =IF(OR(ISBLANK(H40),ISBLANK(I40)),"",DATEDIF(H40,I40,"Y")) -> 1 | K40: =IF(OR(ISBLANK(H40),ISBLANK(I40),ISBLANK(H5)),"",IF(OR(AND(H40>H5,H40<Menu!S73),AND(I40>H5,I40<Menu!S73),AND(H40<H5,I40>Menu!S73)),"Valid","Tidak Valid")) -> Valid | L40: Bukti-bukti Pelaksanaan (Laporan, Hasil Kerjasama, Luaran Kerjasama)
A41: 29 | B41: Universiti Putra Malaysia | C41: V | F41: Kerjasama Pendidikan Perkuliahan Summer Course | G41: Peningkatan Kualitas Pendidikan, Transfer Pengetahuan, Penelitian | H41: 43617 | I41: 46022 | J41: =IF(OR(ISBLANK(H41),ISBLANK(I41)),"",DATEDIF(H41,I41,"Y")) -> 6 | K41: =IF(OR(ISBLANK(H41),ISBLANK(I41),ISBLANK(H5)),"",IF(OR(AND(H41>H5,H41<Menu!S73),AND(I41>H5,I41<Menu!S73),AND(H41<H5,I41>Menu!S73)),"Valid","Tidak Valid")) -> Valid | L41: Bukti-bukti Pelaksanaan (Laporan, Hasil Kerjasama, Luaran Kerjasama)
...

Sheet 2a2
A1: Tabel 2 Kerjasama Tridharma Perguruan Tinggi | G1: sudah ada bukti | M1: <<< Daftar Tabel
A2: Tabel 2 Bagian-2 Kerjasama Penelitian
A3: Diisi oleh pengusul dari Program Studi untuk semua program
B5: Check
B7: V
A9: No. | B9: Lembaga Mitra | C9: Tingkat | F9: Judul Kegiatan Kerjasama | G9: Manfaat bagi PS yang Diakreditasi | H9: Tanggal Awal Kerjasama (HH/BB/TTTT) | I9: Tanggal Akhir Kerjasama (HH/BB/TTTT) | J9: Durasi (dalam tahun) | K9: Status Kerjasama | L9: Bukti Kerjasama
C10: Interna-sional | D10: Nasional | E10: Lokal/Wilayah
A11: 1 | B11: 2 | C11: 3 | D11: 4 | E11: 5 | F11: 6 | G11: 7 | H11: 8 | I11: 9 | J11: 10 | K11: 11 | L11: 12
A12: 1 | B12: Wocare Center | D12: V | F12: Kerjasama Pendidikan dan Penelitian Tugas Akhir Produta dan Proyek Investigasi | G12: Peningkatan Kualitas Pendidikan, Transfer Pengetahuan, Penelitian | H12: 45139 | I12: 45534 | J12: 1 | K12: =IF(OR(ISBLANK(H12),ISBLANK(I12),ISBLANK('2a1'!H5)),"",IF(OR(AND(H12>'2a1'!H5,H12<Menu!S73),AND(I12>'2a1'!H5,I12<Menu!S73),AND(H12<'2a1'!H5,I12>Menu!S73)),"Valid","Tidak Valid")) -> Valid | L12: Bukti-bukti Pelaksanaan (Laporan, Hasil Kerjasama, Luaran Kerjasama)
A13: 2 | B13: PT. Toyota Motor Manufacturing Indonesia | D13: V | F13: Kerjasama Pendidikan dan Penelitian Tugas Akhir Produta | G13: Peningkatan Kualitas Pendidikan, Transfer Pengetahuan, Penelitian | H13: 45323 | I13: 45534 | J13: 0 | K13: =IF(OR(ISBLANK(H13),ISBLANK(I13),ISBLANK('2a1'!H5)),"",IF(OR(AND(H13>'2a1'!H5,H13<Menu!S73),AND(I13>'2a1'!H5,I13<Menu!S73),AND(H13<'2a1'!H5,I13>Menu!S73)),"Valid","Tidak Valid")) -> Valid | L13: Bukti-bukti Pelaksanaan (Laporan, Hasil Kerjasama, Luaran Kerjasama) | N13: INFO
A14: 3 | B14: PT. Berkasih Sinar Utami | D14: V | F14: Kerjasama Pendidikan dan Penelitian Tugas Akhir Produta | G14: Peningkatan Kualitas Pendidikan, Transfer Pengetahuan, Penelitian | H14: 45323 | I14: 45534 | J14: 0 | K14: =IF(OR(ISBLANK(H14),ISBLANK(I14),ISBLANK('2a1'!H5)),"",IF(OR(AND(H14>'2a1'!H5,H14<Menu!S73),AND(I14>'2a1'!H5,I14<Menu!S73),AND(H14<'2a1'!H5,I14>Menu!S73)),"Valid","Tidak Valid")) -> Valid | L14: Bukti-bukti Pelaksanaan (Laporan, Hasil Kerjasama, Luaran Kerjasama) | N14: Jumlah Kerjasama Penelitian | Q14: =SUM(Q17,Q20,Q22) -> 101
A15: 4 | B15: PT. Eteris Prima Wiyasa | D15: V | F15: Kerjasama Pendidikan dan Penelitian Tugas Akhir Produta | G15: Peningkatan Kualitas Pendidikan, Transfer Pengetahuan, Penelitian | H15: 45323 | I15: 45899 | J15: 0 | K15: =IF(OR(ISBLANK(H15),ISBLANK(I15),ISBLANK('2a1'!H5)),"",IF(OR(AND(H15>'2a1'!H5,H15<Menu!S73),AND(I15>'2a1'!H5,I15<Menu!S73),AND(H15<'2a1'!H5,I15>Menu!S73)),"Valid","Tidak Valid")) -> Valid | L15: Bukti-bukti Pelaksanaan (Laporan, Hasil Kerjasama, Luaran Kerjasama)
A16: 5 | B16: PT. Essodev Agro Lestari | D16: V | F16: Kerjasama Pendidikan dan Penelitian Tugas Akhir Produta | G16: Peningkatan Kualitas Pendidikan, Transfer Pengetahuan, Penelitian | H16: 45323 | I16: 45534 | J16: 0 | K16: =IF(OR(ISBLANK(H16),ISBLANK(I16),ISBLANK('2a1'!H5)),"",IF(OR(AND(H16>'2a1'!H5,H16<Menu!S73),AND(I16>'2a1'!H5,I16<Menu!S73),AND(H16<'2a1'!H5,I16>Menu!S73)),"Valid","Tidak Valid")) -> Valid | L16: Bukti-bukti Pelaksanaan (Laporan, Hasil Kerjasama, Luaran Kerjasama)
A17: 6 | B17: PT. Kelola Mina Laut | D17: V | F17: Kerjasama Pendidikan dan Penelitian Tugas Akhir Produta | G17: Peningkatan Kualitas Pendidikan, Transfer Pengetahuan, Penelitian | H17: 45323 | I17: 45534 | J17: 0 | K17: =IF(OR(ISBLANK(H17),ISBLANK(I17),ISBLANK('2a1'!H5)),"",IF(OR(AND(H17>'2a1'!H5,H17<Menu!S73),AND(I17>'2a1'!H5,I17<Menu!S73),AND(H17<'2a1'!H5,I17>Menu!S73)),"Valid","Tidak Valid")) -> Valid | L17: Bukti-bukti Pelaksanaan (Laporan, Hasil Kerjasama, Luaran Kerjasama) | N17: Jumlah Kerjasama Tingkat Internasional | Q17: =COUNTIFS(B12:B957,"<>",C12:C957,"<>",F12:F957,"<>",J12:J957,"<>",K12:K957,"Valid",L12:L957,"<>",C12:C957,"V") -> 3
A18: 7 | B18: PT. Laris Manis Utama | D18: V | F18: Kerjasama Pendidikan dan Penelitian Tugas Akhir Produta | G18: Peningkatan Kualitas Pendidikan, Transfer Pengetahuan, Penelitian | H18: 44247 | I18: 45343 | J18: 4 | K18: =IF(OR(ISBLANK(H18),ISBLANK(I18),ISBLANK('2a1'!H5)),"",IF(OR(AND(H18>'2a1'!H5,H18<Menu!S73),AND(I18>'2a1'!H5,I18<Menu!S73),AND(H18<'2a1'!H5,I18>Menu!S73)),"Valid","Tidak Valid")) -> Valid | L18: Bukti-bukti Pelaksanaan (Laporan, Hasil Kerjasama, Luaran Kerjasama)
A19: 8 | B19: PT. Cinta Bumi Nusantara | D19: V | F19: Kerjasama Pendidikan dan Penelitian Tugas Akhir Produta | G19: Peningkatan Kualitas Pendidikan, Transfer Pengetahuan, Penelitian | H19: 45323 | I19: 45534 | J19: 0 | K19: =IF(OR(ISBLANK(H19),ISBLANK(I19),ISBLANK('2a1'!H5)),"",IF(OR(AND(H19>'2a1'!H5,H19<Menu!S73),AND(I19>'2a1'!H5,I19<Menu!S73),AND(H19<'2a1'!H5,I19>Menu!S73)),"Valid","Tidak Valid")) -> Valid | L19: Bukti-bukti Pelaksanaan (Laporan, Hasil Kerjasama, Luaran Kerjasama)
A20: 9 | B20: PT. Agro Boga Utama | D20: V | F20: Kerjasama Pendidikan dan Penelitian Tugas Akhir Produta | G20: Peningkatan Kualitas Pendidikan, Transfer Pengetahuan, Penelitian | H20: 44593 | I20: 45899 | J20: 3 | K20: =IF(OR(ISBLANK(H20),ISBLANK(I20),ISBLANK('2a1'!H5)),"",IF(OR(AND(H20>'2a1'!H5,H20<Menu!S73),AND(I20>'2a1'!H5,I20<Menu!S73),AND(H20<'2a1'!H5,I20>Menu!S73)),"Valid","Tidak Valid")) -> Valid | L20: Bukti-bukti Pelaksanaan (Laporan, Hasil Kerjasama, Luaran Kerjasama) | N20: Jumlah Kerjasama Tingkat Nasional | Q20: =COUNTIFS(B12:B957,"<>",D12:D957,"<>",F12:F957,"<>",J12:J957,"<>",K12:K957,"Valid",L12:L957,"<>",D12:D957,"V") -> 79
A21: 10 | B21: Aquila Herb | D21: V | F21: Kerjasama Pendidikan dan Penelitian Tugas Akhir Produta | G21: Peningkatan Kualitas Pendidikan, Transfer Pengetahuan, Penelitian | H21: 45323 | I21: 45534 | J21: 0 | K21: =IF(OR(ISBLANK(H21),ISBLANK(I21),ISBLANK('2a1'!H5)),"",IF(OR(AND(H21>'2a1'!H5,H21<Menu!S73),AND(I21>'2a1'!H5,I21<Menu!S73),AND(H21<'2a1'!H5,I21>Menu!S73)),"Valid","Tidak Valid")) -> Valid | L21: Bukti-bukti Pelaksanaan (Laporan, Hasil Kerjasama, Luaran Kerjasama)
A22: 11 | B22: Pengrajin Batik Lasem | E22: V | F22: Kerjasama Pendidikan dan Penelitian Tugas Akhir Produta | G22: Peningkatan Kualitas Pendidikan, Transfer Pengetahuan, Penelitian | H22: 45323 | I22: 45534 | J22: 0 | K22: =IF(OR(ISBLANK(H22),ISBLANK(I22),ISBLANK('2a1'!H5)),"",IF(OR(AND(H22>'2a1'!H5,H22<Menu!S73),AND(I22>'2a1'!H5,I22<Menu!S73),AND(H22<'2a1'!H5,I22>Menu!S73)),"Valid","Tidak Valid")) -> Valid | L22: Bukti-bukti Pelaksanaan (Laporan, Hasil Kerjasama, Luaran Kerjasama) | N22: Jumlah Kerjasama Tingkat Lokal/Wilayah | Q22: =COUNTIFS(B12:B957,"<>",E12:E957,"<>",F12:F957,"<>",J12:J957,"<>",K12:K957,"Valid",L12:L957,"<>",E12:E957,"V") -> 19
A23: 12 | B23: Pondok Sagu Metro | E23: V | F23: Kerjasama Pendidikan dan Penelitian Tugas Akhir Produta | G23: Peningkatan Kualitas Pendidikan, Transfer Pengetahuan, Penelitian | H23: 44593 | I23: 45899 | J23: 2 | K23: =IF(OR(ISBLANK(H23),ISBLANK(I23),ISBLANK('2a1'!H5)),"",IF(OR(AND(H23>'2a1'!H5,H23<Menu!S73),AND(I23>'2a1'!H5,I23<Menu!S73),AND(H23<'2a1'!H5,I23>Menu!S73)),"Valid","Tidak Valid")) -> Valid | L23: Bukti-bukti Pelaksanaan (Laporan, Hasil Kerjasama, Luaran Kerjasama)
A24: 13 | B24: PT. Karya Baru Kita | D24: V | F24: Kerjasama Pendidikan dan Penelitian Tugas Akhir Produta | G24: Peningkatan Kualitas Pendidikan, Transfer Pengetahuan, Penelitian | H24: 45323 | I24: 45534 | J24: 0 | K24: =IF(OR(ISBLANK(H24),ISBLANK(I24),ISBLANK('2a1'!H5)),"",IF(OR(AND(H24>'2a1'!H5,H24<Menu!S73),AND(I24>'2a1'!H5,I24<Menu!S73),AND(H24<'2a1'!H5,I24>Menu!S73)),"Valid","Tidak Valid")) -> Valid | L24: Bukti-bukti Pelaksanaan (Laporan, Hasil Kerjasama, Luaran Kerjasama)
A25: 14 | B25: PT. Unilever Indonesia, Tbk. | D25: V | F25: Kerjasama Pendidikan dan Penelitian Tugas Akhir Produta | G25: Peningkatan Kualitas Pendidikan, Transfer Pengetahuan, Penelitian | H25: 45323 | I25: 45534 | J25: 0 | K25: =IF(OR(ISBLANK(H25),ISBLANK(I25),ISBLANK('2a1'!H5)),"",IF(OR(AND(H25>'2a1'!H5,H25<Menu!S73),AND(I25>'2a1'!H5,I25<Menu!S73),AND(H25<'2a1'!H5,I25>Menu!S73)),"Valid","Tidak Valid")) -> Valid | L25: Bukti-bukti Pelaksanaan (Laporan, Hasil Kerjasama, Luaran Kerjasama)
A26: 15 | B26: PT. Primafood Relasi Utama | D26: V | F26: Kerjasama Pendidikan dan Penelitian Tugas Akhir Produta | G26: Peningkatan Kualitas Pendidikan, Transfer Pengetahuan, Penelitian | H26: 45323 | I26: 45534 | J26: 0 | K26: =IF(OR(ISBLANK(H26),ISBLANK(I26),ISBLANK('2a1'!H5)),"",IF(OR(AND(H26>'2a1'!H5,H26<Menu!S73),AND(I26>'2a1'!H5,I26<Menu!S73),AND(H26<'2a1'!H5,I26>Menu!S73)),"Valid","Tidak Valid")) -> Valid | L26: Bukti-bukti Pelaksanaan (Laporan, Hasil Kerjasama, Luaran Kerjasama)
A27: 16 | B27: PT. LeGGit Boga Mandiri | D27: V | F27: Kerjasama Pendidikan dan Penelitian Tugas Akhir Produta | G27: Peningkatan Kualitas Pendidikan, Transfer Pengetahuan, Penelitian | H27: 44958 | I27: 45899 | J27: 2 | K27: =IF(OR(ISBLANK(H27),ISBLANK(I27),ISBLANK('2a1'!H5)),"",IF(OR(AND(H27>'2a1'!H5,H27<Menu!S73),AND(I27>'2a1'!H5,I27<Menu!S73),AND(H27<'2a1'!H5,I27>Menu!S73)),"Valid","Tidak Valid")) -> Valid | L27: Bukti-bukti Pelaksanaan (Laporan, Hasil Kerjasama, Luaran Kerjasama)
A28: 17 | B28: BUMD Dharma Jaya | D28: V | F28: Kerjasama Pendidikan dan Penelitian Tugas Akhir Produta | G28: Peningkatan Kualitas Pendidikan, Transfer Pengetahuan, Penelitian | H28: 45323 | I28: 45534 | J28: 0 | K28: =IF(OR(ISBLANK(H28),ISBLANK(I28),ISBLANK('2a1'!H5)),"",IF(OR(AND(H28>'2a1'!H5,H28<Menu!S73),AND(I28>'2a1'!H5,I28<Menu!S73),AND(H28<'2a1'!H5,I28>Menu!S73)),"Valid","Tidak Valid")) -> Valid | L28: Bukti-bukti Pelaksanaan (Laporan, Hasil Kerjasama, Luaran Kerjasama)
A29: 18 | B29: PT. Alam Raya Raharja | D29: V | F29: Kerjasama Pendidikan dan Penelitian Tugas Akhir Produta | G29: Peningkatan Kualitas Pendidikan, Transfer Pengetahuan, Penelitian | H29: 45323 | I29: 45534 | J29: 0 | K29: =IF(OR(ISBLANK(H29),ISBLANK(I29),ISBLANK('2a1'!H5)),"",IF(OR(AND(H29>'2a1'!H5,H29<Menu!S73),AND(I29>'2a1'!H5,I29<Menu!S73),AND(H29<'2a1'!H5,I29>Menu!S73)),"Valid","Tidak Valid")) -> Valid | L29: Bukti-bukti Pelaksanaan (Laporan, Hasil Kerjasama, Luaran Kerjasama)
A30: 19 | B30: CV. Bio Chitosan Indonesia | D30: V | F30: Kerjasama Pendidikan dan Penelitian Tugas Akhir Produta | G30: Peningkatan Kualitas Pendidikan, Transfer Pengetahuan, Penelitian | H30: 45323 | I30: 45534 | J30: 0 | K30: =IF(OR(ISBLANK(H30),ISBLANK(I30),ISBLANK('2a1'!H5)),"",IF(OR(AND(H30>'2a1'!H5,H30<Menu!S73),AND(I30>'2a1'!H5,I30<Menu!S73),AND(H30<'2a1'!H5,I30>Menu!S73)),"Valid","Tidak Valid")) -> Valid | L30: Bukti-bukti Pelaksanaan (Laporan, Hasil Kerjasama, Luaran Kerjasama)
A31: 20 | B31: Perum BULOG | D31: V | F31: Kerjasama Pendidikan dan Penelitian Tugas Akhir Produta | G31: Peningkatan Kualitas Pendidikan, Transfer Pengetahuan, Penelitian | H31: 44958 | I31: 45899 | J31: 2 | K31: =IF(OR(ISBLANK(H31),ISBLANK(I31),ISBLANK('2a1'!H5)),"",IF(OR(AND(H31>'2a1'!H5,H31<Menu!S73),AND(I31>'2a1'!H5,I31<Menu!S73),AND(H31<'2a1'!H5,I31>Menu!S73)),"Valid","Tidak Valid")) -> Valid | L31: Bukti-bukti Pelaksanaan (Laporan, Hasil Kerjasama, Luaran Kerjasama)
A32: 21 | B32: Koperasi Jasa Amanah Madani Halal (SIJAMAL) | E32: V | F32: Kerjasama Pendidikan dan Penelitian Tugas Akhir Produta | G32: Peningkatan Kualitas Pendidikan, Transfer Pengetahuan, Penelitian | H32: 45323 | I32: 45534 | J32: 0 | K32: =IF(OR(ISBLANK(H32),ISBLANK(I32),ISBLANK('2a1'!H5)),"",IF(OR(AND(H32>'2a1'!H5,H32<Menu!S73),AND(I32>'2a1'!H5,I32<Menu!S73),AND(H32<'2a1'!H5,I32>Menu!S73)),"Valid","Tidak Valid")) -> Valid | L32: Bukti-bukti Pelaksanaan (Laporan, Hasil Kerjasama, Luaran Kerjasama)
A33: 22 | B33: PT. Liza Herbal Internasional | D33: V | F33: Kerjasama Pendidikan dan Penelitian Tugas Akhir Produta | G33: Peningkatan Kualitas Pendidikan, Transfer Pengetahuan, Penelitian | H33: 44593 | I33: 45899 | J33: 2 | K33: =IF(OR(ISBLANK(H33),ISBLANK(I33),ISBLANK('2a1'!H5)),"",IF(OR(AND(H33>'2a1'!H5,H33<Menu!S73),AND(I33>'2a1'!H5,I33<Menu!S73),AND(H33<'2a1'!H5,I33>Menu!S73)),"Valid","Tidak Valid")) -> Valid | L33: Bukti-bukti Pelaksanaan (Laporan, Hasil Kerjasama, Luaran Kerjasama)
A34: 23 | B34: PT. Sukaraja Pangan Utama | D34: V | F34: Kerjasama Pendidikan dan Penelitian Tugas Akhir Produta | G34: Peningkatan Kualitas Pendidikan, Transfer Pengetahuan, Penelitian | H34: 44958 | I34: 45899 | J34: 2 | K34: =IF(OR(ISBLANK(H34),ISBLANK(I34),ISBLANK('2a1'!H5)),"",IF(OR(AND(H34>'2a1'!H5,H34<Menu!S73),AND(I34>'2a1'!H5,I34<Menu!S73),AND(H34<'2a1'!H5,I34>Menu!S73)),"Valid","Tidak Valid")) -> Valid | L34: Bukti-bukti Pelaksanaan (Laporan, Hasil Kerjasama, Luaran Kerjasama)
A35: 24 | B35: PT. Ratu Bio Indonesia | D35: V | F35: Kerjasama Pendidikan dan Penelitian Tugas Akhir Produta dan Magang MBKM | G35: Peningkatan Kualitas Pendidikan, Transfer Pengetahuan, Penelitian | H35: 44958 | I35: 45899 | J35: 2 | K35: =IF(OR(ISBLANK(H35),ISBLANK(I35),ISBLANK('2a1'!H5)),"",IF(OR(AND(H35>'2a1'!H5,H35<Menu!S73),AND(I35>'2a1'!H5,I35<Menu!S73),AND(H35<'2a1'!H5,I35>Menu!S73)),"Valid","Tidak Valid")) -> Valid | L35: Bukti-bukti Pelaksanaan (Laporan, Hasil Kerjasama, Luaran Kerjasama)
A36: 25 | B36: PT. Pertamina (Persero) | D36: V | F36: Kerjasama Pendidikan dan Penelitian Tugas Akhir Produta | G36: Peningkatan Kualitas Pendidikan, Transfer Pengetahuan, Penelitian | H36: 44958 | I36: 45899 | J36: 2 | K36: =IF(OR(ISBLANK(H36),ISBLANK(I36),ISBLANK('2a1'!H5)),"",IF(OR(AND(H36>'2a1'!H5,H36<Menu!S73),AND(I36>'2a1'!H5,I36<Menu!S73),AND(H36<'2a1'!H5,I36>Menu!S73)),"Valid","Tidak Valid")) -> Valid | L36: Bukti-bukti Pelaksanaan (Laporan, Hasil Kerjasama, Luaran Kerjasama)
A37: 26 | B37: BRIX Stevia | D37: V | F37: Kerjasama Pendidikan dan Penelitian Tugas Akhir Produta | G37: Peningkatan Kualitas Pendidikan, Transfer Pengetahuan, Penelitian | H37: 44958 | I37: 45899 | J37: 2 | K37: =IF(OR(ISBLANK(H37),ISBLANK(I37),ISBLANK('2a1'!H5)),"",IF(OR(AND(H37>'2a1'!H5,H37<Menu!S73),AND(I37>'2a1'!H5,I37<Menu!S73),AND(H37<'2a1'!H5,I37>Menu!S73)),"Valid","Tidak Valid")) -> Valid | L37: Bukti-bukti Pelaksanaan (Laporan, Hasil Kerjasama, Luaran Kerjasama)
A38: 27 | B38: PT. Fontera | D38: V | F38: Kerjasama Pendidikan dan Penelitian | G38: Peningkatan Kualitas Pendidikan, Transfer Pengetahuan, Penelitian | J38: 6 bulan | K38: =IF(OR(ISBLANK(H38),ISBLANK(I38),ISBLANK('2a1'!H5)),"",IF(OR(AND(H38>'2a1'!H5,H38<Menu!S73),AND(I38>'2a1'!H5,I38<Menu!S73),AND(H38<'2a1'!H5,I38>Menu!S73)),"Valid","Tidak Valid")) | L38: Bukti-bukti Pelaksanaan (Laporan, Hasil Kerjasama, Luaran Kerjasama)
A39: 28 | B39: PT. Cisarua Mountain Dairy (CMD) | D39: V | F39: Kerjasama Pendidikan dan Penelitian | G39: Peningkatan Kualitas Pendidikan, Transfer Pengetahuan, Penelitian | J39: 6 bulan | K39: =IF(OR(ISBLANK(H39),ISBLANK(I39),ISBLANK('2a1'!H5)),"",IF(OR(AND(H39>'2a1'!H5,H39<Menu!S73),AND(I39>'2a1'!H5,I39<Menu!S73),AND(H39<'2a1'!H5,I39>Menu!S73)),"Valid","Tidak Valid")) | L39: Bukti-bukti Pelaksanaan (Laporan, Hasil Kerjasama, Luaran Kerjasama)
A40: 29 | B40: CV. Cita Nasional | D40: V | F40: Kerjasama Pendidikan dan Penelitian | G40: Peningkatan Kualitas Pendidikan, Transfer Pengetahuan, Penelitian | J40: 6 bulan | K40: =IF(OR(ISBLANK(H40),ISBLANK(I40),ISBLANK('2a1'!H5)),"",IF(OR(AND(H40>'2a1'!H5,H40<Menu!S73),AND(I40>'2a1'!H5,I40<Menu!S73),AND(H40<'2a1'!H5,I40>Menu!S73)),"Valid","Tidak Valid")) | L40: Bukti-bukti Pelaksanaan (Laporan, Hasil Kerjasama, Luaran Kerjasama)
A41: 30 | B41: PT. Bridgestone Tire Indonesia | D41: V | F41: Kerjasama Pendidikan dan Penelitian | G41: Peningkatan Kualitas Pendidikan, Transfer Pengetahuan, Penelitian | H41: 44593 | I41: 44926 | J41: 1 | K41: =IF(OR(ISBLANK(H41),ISBLANK(I41),ISBLANK('2a1'!H5)),"",IF(OR(AND(H41>'2a1'!H5,H41<Menu!S73),AND(I41>'2a1'!H5,I41<Menu!S73),AND(H41<'2a1'!H5,I41>Menu!S73)),"Valid","Tidak Valid")) -> Valid | L41: Bukti-bukti Pelaksanaan (Laporan, Hasil Kerjasama, Luaran Kerjasama)
A42: 31 | B42: Queensland University | C42: V | F42: Kerjasama Pendidikan dan Penelitian | G42: Peningkatan Kualitas Pendidikan, Transfer Pengetahuan, Penelitian | H42: 45343 | I42: 45535 | J42: 0 | K42: =IF(OR(ISBLANK(H42),ISBLANK(I42),ISBLANK('2a1'!H5)),"",IF(OR(AND(H42>'2a1'!H5,H42<Menu!S73),AND(I42>'2a1'!H5,I42<Menu!S73),AND(H42<'2a1'!H5,I42>Menu!S73)),"Valid","Tidak Valid")) -> Valid | L42: Bukti-bukti Pelaksanaan (Laporan, Hasil Kerjasama, Luaran Kerjasama)
A43: 32 | B43: PG Tersana Baru | D43: V | F43: Kerjasama Pendidikan dan Penelitian | G43: Peningkatan Kualitas Pendidikan, Transfer Pengetahuan, Penelitian | J43: 6 bulan | K43: =IF(OR(ISBLANK(H43),ISBLANK(I43),ISBLANK('2a1'!H5)),"",IF(OR(AND(H43>'2a1'!H5,H43<Menu!S73),AND(I43>'2a1'!H5,I43<Menu!S73),AND(H43<'2a1'!H5,I43>Menu!S73)),"Valid","Tidak Valid")) | L43: Bukti-bukti Pelaksanaan (Laporan, Hasil Kerjasama, Luaran Kerjasama)
...

Sheet 2a3
A1: Tabel 2 Kerjasama Tridharma Perguruan Tinggi | G1: sudah ada bukti | M1: <<< Daftar Tabel
A2: Tabel 2 Bagian-3 Kerjasama Pengabdian kepada Masyarakat
A3: Diisi oleh pengusul dari Program Studi untuk semua program
B5: Check
B7: V
A9: No. | B9: Lembaga Mitra | C9: Tingkat | F9: Judul Kegiatan Kerjasama | G9: Manfaat bagi PS yang Diakreditasi | H9: Tanggal Awal Kerjasama (HH/BB/TTTT) | I9: Tanggal Akhir Kerjasama (HH/BB/TTTT) | J9: Durasi (dalam tahun) | K9: Status Kerjasama | L9: Bukti Kerjasama
C10: Interna-sional | D10: Nasional | E10: Lokal/Wilayah
A11: 1 | B11: 2 | C11: 3 | D11: 4 | E11: 5 | F11: 6 | G11: 7 | H11: 8 | I11: 9 | J11: 10 | L11: 11
A12: 1 | B12: PT. Pramana Pangan Utama | D12: V | F12: Pemeriksaan sampel laboratorium uji | G12: Peningkatan Kualitas Penelitian dan Pengabdian Kepada Masyarakat | H12: 45330 | I12: 45696 | J12: 2024-2025 | K12: =IF(OR(ISBLANK(H12),ISBLANK(I12),ISBLANK('2a1'!H5)),"",IF(OR(AND(H12>'2a1'!H5,H12<Menu!S73),AND(I12>'2a1'!H5,I12<Menu!S73),AND(H12<'2a1'!H5,I12>Menu!S73)),"Valid","Tidak Valid")) -> Valid | L12: Bukti-bukti Pelaksanaan (Laporan, Hasil Kerjasama, Luaran Kerjasama)
A13: 2 | B13: PT. Dagsap Endura Eatore | D13: V | F13: Pemeriksaan sampel laboratorium uji | G13: Peningkatan Kualitas Penelitian dan Pengabdian Kepada Masyarakat | H13: 45352 | I13: 45717 | J13: 1 Tahun | K13: =IF(OR(ISBLANK(H13),ISBLANK(I13),ISBLANK('2a1'!H5)),"",IF(OR(AND(H13>'2a1'!H5,H13<Menu!S73),AND(I13>'2a1'!H5,I13<Menu!S73),AND(H13<'2a1'!H5,I13>Menu!S73)),"Valid","Tidak Valid")) -> Valid | L13: Bukti-bukti Pelaksanaan (Laporan, Hasil Kerjasama, Luaran Kerjasama) | N13: INFO
A14: 3 | B14: PT. Vosen Pratita Kemindo | D14: V | F14: Pemeriksaan sampel laboratorium uji | G14: Peningkatan Kualitas Penelitian dan Pengabdian Kepada Masyarakat | H14: 45958 | I14: 46323 | J14: 1 Tahun | K14: =IF(OR(ISBLANK(H14),ISBLANK(I14),ISBLANK('2a1'!H5)),"",IF(OR(AND(H14>'2a1'!H5,H14<Menu!S73),AND(I14>'2a1'!H5,I14<Menu!S73),AND(H14<'2a1'!H5,I14>Menu!S73)),"Valid","Tidak Valid")) -> Valid | L14: Bukti-bukti Pelaksanaan (Laporan, Hasil Kerjasama, Luaran Kerjasama) | N14: Jumlah Kerjasama PkM | Q14: =SUM(Q17,Q20,Q23) -> 37
A15: 4 | B15: PT. Agrinusa Jaya Santosa | D15: V | F15: Pemeriksaan sampel laboratorium uji | G15: Peningkatan jejaring dan pengembangan keilmuan | H15: 44808 | I15: 44834 | J15: 0 | K15: =IF(OR(ISBLANK(H15),ISBLANK(I15),ISBLANK('2a1'!H5)),"",IF(OR(AND(H15>'2a1'!H5,H15<Menu!S73),AND(I15>'2a1'!H5,I15<Menu!S73),AND(H15<'2a1'!H5,I15>Menu!S73)),"Valid","Tidak Valid")) -> Valid | L15: Bukti-bukti Pelaksanaan (Laporan, Hasil Kerjasama, Luaran Kerjasama)
A16: 5 | B16: PT. Simex Pharmaceutical | D16: V | F16: Pemeriksaan sampel laboratorium uji | G16: Peningkatan Kualitas Penelitian dan Pengabdian Kepada Masyarakat | J16: 2024-2025 | K16: =IF(OR(ISBLANK(H16),ISBLANK(I16),ISBLANK('2a1'!H5)),"",IF(OR(AND(H16>'2a1'!H5,H16<Menu!S73),AND(I16>'2a1'!H5,I16<Menu!S73),AND(H16<'2a1'!H5,I16>Menu!S73)),"Valid","Tidak Valid")) | L16: Bukti-bukti Pelaksanaan (Laporan, Hasil Kerjasama, Luaran Kerjasama)
A17: 6 | B17: PT. Vaksindo Satwa Nusantara Plant 1 | D17: V | F17: Pemeriksaan sampel laboratorium uji | G17: Peningkatan Kualitas Penelitian dan Pengabdian Kepada Masyarakat | J17: 2024-2025 | K17: =IF(OR(ISBLANK(H17),ISBLANK(I17),ISBLANK('2a1'!H5)),"",IF(OR(AND(H17>'2a1'!H5,H17<Menu!S73),AND(I17>'2a1'!H5,I17<Menu!S73),AND(H17<'2a1'!H5,I17>Menu!S73)),"Valid","Tidak Valid")) | L17: Bukti-bukti Pelaksanaan (Laporan, Hasil Kerjasama, Luaran Kerjasama) | N17: Jumlah Kerjasama Tingkat Internasional | Q17: =COUNTIFS(B12:B999,"<>",C12:C999,"<>",F12:F999,"<>",J12:J999,"<>",K12:K999,"Valid",L12:L999,"<>",C12:C999,"V") -> 6
A18: 7 | B18: PT. Haengnam Sejahtera Indonesia | E18: V | F18: Pemeriksaan laboratorium sampel air limbah | G18: Peningkatan jejaring dan pengembangan keilmuan | H18: 45413 | I18: 45453 | J18: 0 | K18: =IF(OR(ISBLANK(H18),ISBLANK(I18),ISBLANK('2a1'!H5)),"",IF(OR(AND(H18>'2a1'!H5,H18<Menu!S73),AND(I18>'2a1'!H5,I18<Menu!S73),AND(H18<'2a1'!H5,I18>Menu!S73)),"Valid","Tidak Valid")) -> Valid | L18: Bukti-bukti Pelaksanaan (Laporan, Hasil Kerjasama, Luaran Kerjasama)
A19: 8 | B19: PT. Medifarma Laboratories | D19: V | F19: Pemeriksaan sampel laboratorium uji | G19: Peningkatan Kualitas Penelitian dan Pengabdian Kepada Masyarakat | J19: 2024-2025 | K19: =IF(OR(ISBLANK(H19),ISBLANK(I19),ISBLANK('2a1'!H5)),"",IF(OR(AND(H19>'2a1'!H5,H19<Menu!S73),AND(I19>'2a1'!H5,I19<Menu!S73),AND(H19<'2a1'!H5,I19>Menu!S73)),"Valid","Tidak Valid")) | L19: Bukti-bukti Pelaksanaan (Laporan, Hasil Kerjasama, Luaran Kerjasama)
A20: 9 | B20: Taman Safari Indonesia | D20: V | F20: Pemeriksaan sampel laboratorium uji | G20: Peningkatan Kualitas Penelitian dan Pengabdian Kepada Masyarakat | J20: 1 Tahun | K20: =IF(OR(ISBLANK(H20),ISBLANK(I20),ISBLANK('2a1'!H5)),"",IF(OR(AND(H20>'2a1'!H5,H20<Menu!S73),AND(I20>'2a1'!H5,I20<Menu!S73),AND(H20<'2a1'!H5,I20>Menu!S73)),"Valid","Tidak Valid")) | L20: Bukti-bukti Pelaksanaan (Laporan, Hasil Kerjasama, Luaran Kerjasama) | N20: Jumlah Kerjasama Tingkat Nasional | Q20: =COUNTIFS(B12:B999,"<>",D12:D999,"<>",F12:F999,"<>",J12:J999,"<>",K12:K999,"Valid",L12:L999,"<>",D12:D999,"V") -> 17
A21: 10 | B21: PT. Antam, Tbk | D21: V | F21: Pemeriksaan sampel laboratorium uji | G21: Peningkatan Kualitas Penelitian dan Pengabdian Kepada Masyarakat | J21: 2024-2025 | K21: =IF(OR(ISBLANK(H21),ISBLANK(I21),ISBLANK('2a1'!H5)),"",IF(OR(AND(H21>'2a1'!H5,H21<Menu!S73),AND(I21>'2a1'!H5,I21<Menu!S73),AND(H21<'2a1'!H5,I21>Menu!S73)),"Valid","Tidak Valid")) | L21: Bukti-bukti Pelaksanaan (Laporan, Hasil Kerjasama, Luaran Kerjasama)
A22: 11 | B22: PT. Asalta Surya Mandiri | D22: V | F22: Pemeriksaan laboratorium sampel air limbah | G22: Peningkatan jejaring dan pengembangan keilmuan | H22: 44798 | I22: 44798 | J22: 0 | L22: Bukti-bukti Pelaksanaan (Laporan, Hasil Kerjasama, Luaran Kerjasama)
A23: 12 | B23: PT. Bentonit Alam Indonesia | E23: V | F23: Pemeriksaan laboratorium sampel air limbah | G23: Peningkatan jejaring dan pengembangan keilmuan | H23: 45159 | I23: 45159 | J23: 0 | K23: =IF(OR(ISBLANK(H23),ISBLANK(I23),ISBLANK('2a1'!H5)),"",IF(OR(AND(H23>'2a1'!H5,H23<Menu!S73),AND(I23>'2a1'!H5,I23<Menu!S73),AND(H23<'2a1'!H5,I23>Menu!S73)),"Valid","Tidak Valid")) -> Valid | L23: Bukti-bukti Pelaksanaan (Laporan, Hasil Kerjasama, Luaran Kerjasama) | N23: Jumlah Kerjasama Tingkat Lokal/Wilayah | Q23: =COUNTIFS(B12:B999,"<>",E12:E999,"<>",F12:F999,"<>",J12:J999,"<>",K12:K999,"Valid",L12:L999,"<>",E12:E999,"V") -> 14
A24: 13 | B24: PT. Aspex Kumbong | D24: V | F24: Pemeriksaan sampel laboratorium uji | G24: Peningkatan Kualitas Penelitian dan Pengabdian Kepada Masyarakat | J24: 2024-2025 | K24: =IF(OR(ISBLANK(H24),ISBLANK(I24),ISBLANK('2a1'!H5)),"",IF(OR(AND(H24>'2a1'!H5,H24<Menu!S73),AND(I24>'2a1'!H5,I24<Menu!S73),AND(H24<'2a1'!H5,I24>Menu!S73)),"Valid","Tidak Valid")) | L24: Bukti-bukti Pelaksanaan (Laporan, Hasil Kerjasama, Luaran Kerjasama)
A25: 14 | B25: PT. Sunlee Jaya | D25: V | F25: Pemeriksaan sampel laboratorium uji | G25: Peningkatan Kualitas Penelitian dan Pengabdian Kepada Masyarakat | J25: 2024-2025 | K25: =IF(OR(ISBLANK(H25),ISBLANK(I25),ISBLANK('2a1'!H5)),"",IF(OR(AND(H25>'2a1'!H5,H25<Menu!S73),AND(I25>'2a1'!H5,I25<Menu!S73),AND(H25<'2a1'!H5,I25>Menu!S73)),"Valid","Tidak Valid")) | L25: Bukti-bukti Pelaksanaan (Laporan, Hasil Kerjasama, Luaran Kerjasama)
A26: 16 | B26: PT. Getsemani Benindo | D26: V | F26: Pemeriksaan sampel laboratorium uji | G26: Peningkatan Kualitas Penelitian dan Pengabdian Kepada Masyarakat | J26: 2024-2025 | K26: =IF(OR(ISBLANK(H26),ISBLANK(I26),ISBLANK('2a1'!H5)),"",IF(OR(AND(H26>'2a1'!H5,H26<Menu!S73),AND(I26>'2a1'!H5,I26<Menu!S73),AND(H26<'2a1'!H5,I26>Menu!S73)),"Valid","Tidak Valid")) | L26: Bukti-bukti Pelaksanaan (Laporan, Hasil Kerjasama, Luaran Kerjasama)
A27: 17 | B27: PT. Mulia Darma Sarana | D27: V | F27: Pemeriksaan sampel laboratorium uji | G27: Peningkatan Kualitas Penelitian dan Pengabdian Kepada Masyarakat | J27: 1 Tahun | K27: =IF(OR(ISBLANK(H27),ISBLANK(I27),ISBLANK('2a1'!H5)),"",IF(OR(AND(H27>'2a1'!H5,H27<Menu!S73),AND(I27>'2a1'!H5,I27<Menu!S73),AND(H27<'2a1'!H5,I27>Menu!S73)),"Valid","Tidak Valid")) | L27: Bukti-bukti Pelaksanaan (Laporan, Hasil Kerjasama, Luaran Kerjasama)
A28: 18 | B28: PT. Simex Pharmaceutical | D28: V | F28: Pemeriksaan sampel laboratorium uji | G28: Peningkatan Kualitas Penelitian dan Pengabdian Kepada Masyarakat | J28: 2024-2025 | K28: =IF(OR(ISBLANK(H28),ISBLANK(I28),ISBLANK('2a1'!H5)),"",IF(OR(AND(H28>'2a1'!H5,H28<Menu!S73),AND(I28>'2a1'!H5,I28<Menu!S73),AND(H28<'2a1'!H5,I28>Menu!S73)),"Valid","Tidak Valid")) | L28: Bukti-bukti Pelaksanaan (Laporan, Hasil Kerjasama, Luaran Kerjasama)
A29: 19 | B29: PT. Riasima Abadi | E29: V | F29: Pemeriksaan laboratorium sampel air limbah | G29: Peningkatan jejaring dan pengembangan keilmuan | H29: 45260 | I29: 45260 | J29: 0 | K29: =IF(OR(ISBLANK(H29),ISBLANK(I29),ISBLANK('2a1'!H5)),"",IF(OR(AND(H29>'2a1'!H5,H29<Menu!S73),AND(I29>'2a1'!H5,I29<Menu!S73),AND(H29<'2a1'!H5,I29>Menu!S73)),"Valid","Tidak Valid")) -> Valid | L29: Bukti-bukti Pelaksanaan (Laporan, Hasil Kerjasama, Luaran Kerjasama)
A30: 20 | B30: CV. Warisan Matahari Makmur | D30: V | F30: Pemeriksaan sampel laboratorium uji | G30: Peningkatan Kualitas Penelitian dan Pengabdian Kepada Masyarakat | J30: 2024-2025 | K30: =IF(OR(ISBLANK(H30),ISBLANK(I30),ISBLANK('2a1'!H5)),"",IF(OR(AND(H30>'2a1'!H5,H30<Menu!S73),AND(I30>'2a1'!H5,I30<Menu!S73),AND(H30<'2a1'!H5,I30>Menu!S73)),"Valid","Tidak Valid")) | L30: Bukti-bukti Pelaksanaan (Laporan, Hasil Kerjasama, Luaran Kerjasama)
A31: 21 | B31: PT. Pramana Pangan | D31: V | F31: Pemeriksaan sampel laboratorium uji | G31: Peningkatan Kualitas Penelitian dan Pengabdian Kepada Masyarakat | J31: 1 Tahun | K31: =IF(OR(ISBLANK(H31),ISBLANK(I31),ISBLANK('2a1'!H5)),"",IF(OR(AND(H31>'2a1'!H5,H31<Menu!S73),AND(I31>'2a1'!H5,I31<Menu!S73),AND(H31<'2a1'!H5,I31>Menu!S73)),"Valid","Tidak Valid")) | L31: Bukti-bukti Pelaksanaan (Laporan, Hasil Kerjasama, Luaran Kerjasama)
